Workbook

Sheet Export
A1: model | B1: sku | C1: price | D1: description | E1: notes
A2: 18W040SH | B2: 18W040SH_u1 | C2: =VLOOKUP(A2,References!$C:$D,2,0) -> 231.9598
A3: 14G020SH | B3: 14G020SH | C3: =VLOOKUP(A3,References!$C:$D,2,0) -> 191.53527
A4: 10W040SH | B4: 10W040SH | C4: =VLOOKUP(A4,References!$C:$D,2,0) -> 144.25
A5: 18Y012SH | B5: 18Y012SH | C5: =VLOOKUP(A5,References!$C:$D,2,0) -> 231.9598
A6: 18W060SH | B6: 18W060SH_u1 | C6: =VLOOKUP(A6,References!$C:$D,2,0) -> 231.9598
A7: 18W040SH | B7: 18W040SH | C7: =VLOOKUP(A7,References!$C:$D,2,0) -> 231.9598
A8: 18Y2.5MMSH | B8: 18Y2.5MMSH | C8: =VLOOKUP(A8,References!$C:$D,2,0) -> 231.9598
A9: 18Y3MMSH | B9: 18Y3MMSH | C9: =VLOOKUP(A9,References!$C:$D,2,0) -> 231.9598
A10: BRASS030SH | B10: BRASS030SH | C10: =VLOOKUP(A10,References!$C:$D,2,0) -> 2
A11: FS050SH | B11: FS050SH | C11: =VLOOKUP(A11,References!$C:$D,2,0) -> 106.69782
A12: 14Y050SH | B12: 14Y050SH_u1 | C12: =VLOOKUP(A12,References!$C:$D,2,0) -> 188.40816
A13: 18Y008SH | B13: 18Y008SH | C13: =VLOOKUP(A13,References!$C:$D,2,0) -> 231.9598
... A1682: 18Y025RSW | B1682: 18Y025RSW_u1 | C1682: =VLOOKUP(A1682,References!$C:$D,2,0) -> 231.9598
A1683: SECS | B1683: SECS | C1683: =Prices!$D$98 -> 100.695
A1684: SHCS | B1684: SHCS | C1684: =Prices!$D$98 -> 100.695
A1685: SMCS | B1685: SMCS | C1685: =Prices!$D$98 -> 100.695
A1686: SSITPRS | B1686: SSITPRS | C1686: =Prices!$D$99 -> 102.065
A1687: SS56PS | B1687: SS56PS | C1687: =Prices!$D$99 -> 102.065
A1688: SS65PRS | B1688: SS65PRS | C1688: =Prices!$D$99 -> 102.065
A1689: SS65PS | B1689: SS65PS | C1689: =Prices!$D$99 -> 102.065
A1690: SS70PRS | B1690: SS70PRS | C1690: =Prices!$D$99 -> 102.065
A1691: SS70PS | B1691: SS70PS | C1691: =Prices!$D$99 -> 102.065
A1692: SS75PRS | B1692: SS75PRS | C1692: =Prices!$D$99 -> 102.065
A1693: SS75PS | B1693: SS75PS | C1693: =Prices!$D$99 -> 102.065
A1694: SSITPS | B1694: SSITPS | C1694: =Prices!$D$99 -> 102.065
A1695: SEPS | B1695: SEPS | C1695: =Prices!$D$99 -> 102.065
A1696: SHPS | B1696: SHPS | C1696: =Prices!$D$99 -> 102.065
A1697: SITPS | B1697: SITPS | C1697: =Prices!$D$99 -> 102.065
A1698: SXESS | B1698: SXESS | C1698: =Prices!$D$97 -> 99.325
A1699: SESS | B1699: SESS | C1699: =Prices!$D$97 -> 99.325
A1700: SESS | B1700: SESS_u1 | C1700: =Prices!$D$97 -> 99.325
A1701: SHSS | B1701: SHSS | C1701: =Prices!$D$97 -> 99.325
A1702: SMSS | B1702: SMSS | C1702: =Prices!$D$97 -> 99.325
A1703: SITSS | B1703: SITSS | C1703: =Prices!$D$97 -> 99.325
A1704: SS045SW | B1704: SS045SW | C1704: =Prices!$D$97 -> 99.325
A1705: SXEWS | B1705: SXEWS | C1705: =Prices!$D$97 -> 99.325
A1706: SEWS | B1706: SEWS | C1706: =Prices!$D$97 -> 99.325
A1707: SEWS | B1707: SEWS_u1 | C1707: =Prices!$D$97 -> 99.325
A1708: SHWS | B1708: SHWS | C1708: =Prices!$D$97 -> 99.325
...

Sheet Prices
E1: MYRON TOBACK INC.
A4: GOLD MARKET | D4: 4616 | G4: GOLD SCRAP | J4: =D4/L4 -> 8.3927273 | K4: per dwt | L4: 550
A5: SILVER MARKET | D5: 68.5 | G5: SILVER SCRAP | J5: =D5/L5 -> 42.02454 | K5: per oz | L5: 1.63
A6: PLATINUM MARKET | D6: 1887
A7: PALLADIUM MARKET | D7: 1375 | L7: PLAT | M7: FINE
G8: PLATINUM WIRE & SHEET | J8: =D6/L8 -> 135.7554 | K8: per dwt | L8: =556/40 -> 13.9 | M8: =319.7/371 -> 0.86172507
A9: FINE GOLD PER OZ | D9: =D4*102% -> 4708.32 | G9: 5 dwt's or more of Platinum | J9: =D6/L9 -> 126.6443 | K9: per dwt | L9: 14.9 | M9: 16.52196
B10: < THAN 1 OZ | D10: =(D4+40)/20 -> 232.8 | G10: PALLADIUM WIRE & SHEET | J10: =D7/L11 -> 90.234375 | K10: per dwt | L10: =556/36 -> 15.444444 | M10: <= PALLADIUM
E11: . | L11: =320/21 -> 15.238095
J12: DWT | K12: GRAM
B13: 14K Rd Wire & Sheet | J13: =D4/L13 -> 188.40816 | K13: =J13/1.55517 -> 121.14956 | L13: 24.5
B15: 14K Sq, 1/2Rd, Tri, Disc | J15: =D4/L15 -> 190.7438 | K15: =J15/1.555517 -> 122.62405 | L15: 24.2
B17: 14K Pin Tong, Spring Sheet, Reg Bezel | J17: =D4/L17 -> 190.7438 | K17: =J17/1.55517 -> 122.65142 | L17: 24.2
B19: 14K Pink & Green Round Wire | J19: =D4/L19 -> 191.53527 | K19: =J19/1.55517 -> 123.16034 | L19: 24.1
B21: 14K Pink & Green 1/2 Rd | J21: =D4/L21 -> 192.33333 | K21: =J21/1.55517 -> 123.67351 | L21: 24
B23: 14K Channel Wire | J23: =D4/L23 -> 196.42553 | K23: =J23/1.55517 -> 126.30486 | L23: 23.5
B25: 14K Tubing, Seated Bezel Wire | J25: =D4/L25 -> 209.81818 | K25: =J25/1.55517 -> 134.91656 | L25: 22
B27: 14K Coiled Tubing | J27: =D4/L27 -> 242.94737 | K27: =J27/1.55517 -> 156.21917 | L27: 19
B29: 14K Twisted Coil Tubing | J29: =D4/L29 -> 256.44444 | K29: =J29/1.55517 -> 164.89801 | L29: 18
B33: 18K Rd Wire & Sheet | J33: =D4/L33 -> 231.9598 | K33: =J33/1.55517 -> 149.15398 | L33: 19.9
B35: 18K 1/2 Rd, Sq Wire & Spring Sheet | J35: =D4/L35 -> 233.13131 | K35: =J35/1.55517 -> 149.90729 | L35: 19.8
B37: 18K Channel Wire | J37: =D4/L37 -> 234.31472 | K37: =J37/1.55517 -> 150.66824 | L37: 19.7
B39: 18K Tubing | J39: =D4/L39 -> 246.84492 | K39: =J39/1.55517 -> 158.72536 | L39: 18.7
B43: 22K Rd Wire | J43: =D4/L43 -> 260.79096 | K43: =J43/1.55517 -> 167.6929 | L43: 17.7
B45: 24K Cloisonne Wire | J45: =D4/L45 -> 307.73333 | K45: =J45/1.55517 -> 197.87762 | L45: 15
B50: 14K DISCOUNT PRICE | E50: GRAM | H50: 18K DISCOUNT PRICE | K50: GRAM | L50: 14 | M50: 18
B51: 1-5 DWT | D51: =D4/L51 -> 184.64 | E51: =D51/1.55517 -> 118.72657 | H51: 1-5 DWT | J51: =D4/M51 -> 230.8 | K51: =J51/1.55517 -> 148.40821 | L51: 25 | M51: 20
B52: 6-10 DWT | D52: =D4/L52 -> 177.53846 | E52: =D52/1.55517 -> 114.16016 | H52: 6-10 DWT | J52: =D4/M52 -> 225.17073 | K52: =J52/1.55517 -> 144.7885 | L52: 26 | M52: 20.5
B53: 11-25 DWT | D53: =D4/L53 -> 174.18868 | E53: =D53/1.55517 -> 112.0062 | H53: 11-25 DWT | J53: =D4/M53 -> 219.80952 | K53: =J53/1.55517 -> 141.34115 | L53: 26.5 | M53: 21
B54: 25 + DWT | D54: =D4/L54 -> 170.96296 | E54: =D54/1.55517 -> 109.93201 | F54: cash only | J54: =D4/M54 -> 209.81818 | K54: =J54/1.55517 -> 134.91656 | L54: 27 | M54: 22
B56: 10K DISCOUNT PRICE | H56: 22K DISCOUNT PRICE | L56: 10 | M56: 22
B57: 1-5 DWT | D57: =D4/L57 -> 144.25 | E57: =D57/1.77717 -> 81.168374 | H57: 1-5 DWT | J57: =D4/M57 -> 260.79096 | K57: =J57/1.55517 -> 167.6929 | L57: 32 | M57: 17.7
B58: 6-10 DWT | D58: =D4/L58 -> 142.03077 | E58: =D58/1.55517 -> 91.328131 | H58: 6-10 DWT | J58: =D4/M58 -> 256.44444 | K58: =J58/1.55517 -> 164.89801 | L58: 32.5 | M58: 18
B59: 11-25 DWT | D59: =D4/L59 -> 130.95035 | E59: =D59/1.55517 -> 84.203241 | H59: 11-25 DWT | J59: =D4/M59 -> 242.94737 | K59: =J59/1.55517 -> 156.21917 | L59: 35.25 | M59: 19
B60: 25 + DWT | D60: =D4/L60 -> 128.22222 | E60: =D60/1.55517 -> 82.449007 | F60: CASH ONLY | J60: =D4/M60 -> 236.71795 | K60: =J60/1.55517 -> 152.21355 | L60: 36 | M60: 19.5
B63: GOLD MARKET | C63: =D4 -> 4616 | F63: GOLD FILLED SCRAP | G63: =C63/H63 -> 76.933333 | H63: 60
B64: SILVER MARKET | C64: =D5 -> 68.5 | F64: SILVER SCRAP | G64: =C64/H64 -> 42.02454 | H64: 1.63
B68: S/S SHEET & WIRE | F68: FINE SILVER SHEET & WIRE | M68: G/F SHEET & WIRE | N68: =D4/P68 -> 220.97861 | O68: 0.52 | P68: 20.8889
B69: 1-9 OZ | D69: =D5/H69 -> 95.938375 | F69: 1----9 OZ | G69: =D5/I69 -> 106.69782 | H69: 0.714 | I69: 0.642 | M69: OVER 5OZS | N69: =D4/P69 -> 205.83802 | O69: 0.54 | P69: 22.4254
B70: 10-49 OZ | D70: =C64/H70 -> 95.006935 | F70: 10---49 OZ | G70: =C64/I70 -> 105.87326 | H70: 0.721 | I70: 0.647
...

Sheet References
A1: brand | B1: description | C1: model | D1: price | F1: qty | G1: model_barcode | H1: shelf | I1: sku | J1: tracking0 | K1: fallback_model_attachments
A2: LEACH GARNER-STERN METALS | B2: 14KW 030 ROUND SOFT WIRE - PALLADIUM | C2: 14KWPD030RSW | D2: =Prices!$J$13+3 -> 191.40816 | F2: 11.53 | G2: XCXLQZQA | H2: Vault | I2: 14KWPD030RSW | J2: WIRE
A3: LEACH GARNER-STERN METALS | B3: 14KW PALLADIUM 040 ROUND SOFT WIRE | C3: 14KWPD040RSW | D3: =Prices!$J$13+3 -> 191.40816 | F3: 136.62 | G3: W5AYKLN2 | H3: Vault | I3: 14KWPD040RSW | J3: WIRE
A4: LEACH GARNER-STERN METALS | B4: 14KY 045 CHANNEL WIRE--PATTERN #4409 | C4: 14KY045CW | D4: =Prices!$J$23 -> 196.42553 | F4: 50.41 | G4: X1DRU2ER | H4: Vault | I4: 14KY045CW | J4: WIRE | K4: 18P038CW_161121-195007.jpg
A5: LEACH GARNER-STERN METALS | B5: 14KP 038 CHANNEL WIRE -PATTERN #3257 | C5: 14P038CW | D5: =Prices!$J$23 -> 196.42553 | F5: 0.51 | G5: 204F8EEP | H5: Vault | I5: 14P038CW | J5: WIRE | K5: 18P038CW.jpg
A6: LEACH GARNER-STERN METALS | B6: 14KP .045 CHANNEL WIRE -PATTERN#4409 | C6: 14P045CW | D6: =Prices!$J$23 -> 196.42553 | F6: 6.68 | G6: AN2LKHDJ | H6: Vault | I6: 14P045CW | J6: WIRE | K6: 18P038CW.jpg
A7: LEACH GARNER-STERN METALS | B7: 14KP .060 CHANNEL WIRE | C7: 14P060CW | D7: =Prices!$J$23 -> 196.42553 | F7: 2.19 | G7: CKV7K742 | H7: Vault | I7: 14P060CW | J7: WIRE
A8: LEACH GARNER-STERN METALS | B8: 14KP .086 CHANNEL WIRE -PATTERN#4414 | C8: 14P086CW | D8: =Prices!$J$23 -> 196.42553 | F8: 37.67 | G8: DAEM6VYM | H8: Vault | I8: 14P086CW | J8: WIRE | K8: 14Y086CW.jpg
A9: HOOVER & STRONG | B9: 14KP 1.7MM X .5MM FLAT WIRE | C9: 14P1.7FLW | D9: =Prices!$J$21 -> 192.33333 | F9: 12.82 | G9: A9J4J4U4 | H9: Vault | I9: 14P1.7FLW | J9: WIRE | K9: 14P1.7FLW.jpg
A10: HOOVER & STRONG | B10: 14KP 11MM X 1.25MM FLAT SHEET | C10: 14P11X1.25FW | D10: =Prices!$J$21 -> 192.33333 | F10: 0 | G10: EA5V4TJE | I10: 14P11X1.25FW | J10: SHEET
A11: HOOVER & STRONG | B11: 14KP 152MM X 18MM FLAT SHEET | C11: 14P152X18X050FW | D11: =Prices!$J$21 -> 192.33333 | F11: 0 | G11: N9Q92ZMT | I11: 14P152X18X050FW | J11: SHEET
A12: HOOVER & STRONG | B12: 14KP 2.5MM X 1.75MM FLAT WIRE | C12: 14P2.5X1.75FW | D12: =Prices!$J$21 -> 192.33333 | F12: 11.26 | G12: RA2E6D6N | H12: Vault | I12: 14P2.5X1.75FW | J12: WIRE
A13: HOOVER & STRONG | B13: 14KP 2MM X 1MM FLAT WIRE | C13: 14P2X1FW | D13: =Prices!$J$21 -> 192.33333 | F13: 32.85 | G13: QCN6AC88 | H13: Vault | I13: 14P2X1FW | J13: WIRE
A14: HOOVER & STRONG | B14: 14KP 3.5MM X 1MM FLAT WIRE | C14: 14P3.5FW | D14: =Prices!$J$21 -> 192.33333 | F14: 35.13 | G14: 10CTEA2K | H14: Vault | I14: 14P3.5FW | J14: WIRE | K14: 5MMBZW.jpg
A15: HOOVER & STRONG | B15: 14KP 3MM X 1MM FLAT WIRE | C15: 14P3X1FW | D15: =Prices!$J$21 -> 192.33333 | F15: 42.82 | G15: KTPEUYX5 | H15: Vault | I15: 14P3X1FW | J15: WIRE | K15: 14W2.0FW.jpg
A16: HOOVER & STRONG | B16: 14KP 4MM ROUND WIRE | C16: 14P4.0RW | D16: =Prices!$J$21 -> 192.33333 | F16: 26.11 | G16: HX5HXM9A | H16: Vault | I16: 14P4.0RW | J16: WIRE | K16: 18P160RSW_161223-150009.jpg
A17: HOOVER & STRONG | B17: 14KP 4MM X 1MM FLAT WIRE | C17: 14P4x1FW | D17: =Prices!$J$21 -> 192.33333 | F17: 15.84 | G17: 4MVTW2Z1 | H17: Vault | I17: 14P4x1FW | J17: WIRE | K17: 18W2.0FW.jpg
A18: HOOVER & STRONG | B18: 14KT PINK GOLD 6X1.25 FLAT WIRE | C18: 14P6X1.25FW | D18: =Prices!$J$21 -> 192.33333 | F18: 11.49 | G18: 65UC3EK7 | H18: Vault | I18: 14P6X1.25FW | J18: WIRE
A19: HOOVER & STRONG | B19: 14KP 6MM X 2MM FLAT WIRE | C19: 14P6x2FW | D19: =Prices!$J$21 -> 192.33333 | F19: 15.88 | G19: 1L9FVJC5 | H19: Vault | I19: 14P6x2FW | J19: WIRE | K19: 18W2.0FW.jpg
A20: HOOVER & STRONG | B20: 14KP 9MM X 1.25MM FLAT WIRE | C20: 14P9X1.25FW | D20: =Prices!$J$21 -> 192.33333 | F20: 28.9 | G20: WUDDVZ85 | H20: Vault | I20: 14P9X1.25FW | J20: WIRE
A21: HOOVER & STRONG | B21: 14KW .5 X .025 FLAT WIRE | C21: 14W.5X.025FW | D21: =Prices!$J$15 -> 190.7438 | F21: 83.01 | G21: 7VDAFP43 | H21: Vault | I21: 14W.5X.025FW | J21: WIRE
A22: HOOVER & STRONG | B22: 14KW .625 X .040 FLAT WIRE | C22: 14W.625X.040FW | D22: =Prices!$J$15 -> 190.7438 | F22: 26.7 | G22: N0NMCU74 | H22: Vault | I22: 14W.625X.040FW | J22: WIRE
A23: ALRUE Do All | B23: 14KW .025 NICKLE FREE SOFT ROUND WIRE | C23: 14W025NCFRW | D23: =Prices!$J$15 -> 190.7438 | F23: 4.56 | G23: FHDY31VX | H23: Vault | I23: 14W025NCFRW | J23: WIRE | K23: 14W025RHW_170515-135120_170515-135500.jpg
A24: LEACH GARNER-STERN METALS | B24: 14KW .038 CHANNEL WIRE -PATTERN#3257 | C24: 14W038CW | D24: =Prices!$J$23 -> 196.42553 | F24: 110.11 | G24: VJAVPEZD | H24: Vault | I24: 14W038CW | J24: WIRE | K24: 14W038CW_190501-134105.jpg
A25: LEACH GARNER-STERN METALS | B25: 14KW 045 CHANNEL WIRE--PATTERN #4409 | C25: 14W045CW | D25: =Prices!$J$23 -> 196.42553 | F25: 40.65 | G25: 939KJAZ4 | H25: Vault | I25: 14W045CW | J25: WIRE | K25: 18P038CW.jpg
A26: LEACH GARNER-STERN METALS | B26: 14KW .052 CHANNEL WIRE | C26: 14W052CW | D26: =Prices!$J$23 -> 196.42553 | F26: 0 | G26: MXH9TDF8 | I26: 14W052CW | J26: WIRE | K26: 14W052CW.jpg
A27: LEACH GARNER-STERN METALS | B27: 14KW .060 CHANNEL WIRE | C27: 14W060CW | D27: =Prices!$J$23 -> 196.42553 | F27: 127.61 | G27: 2L54VWWY | H27: Vault | I27: 14W060CW | J27: WIRE | K27: 14W060CW_180227-162837.jpg
A28: LEACH GARNER-STERN METALS | B28: 14KW .086 CHANNEL WIRE | C28: 14W086CW | D28: =Prices!$J$23 -> 196.42553 | F28: 47.32 | G28: PVRXDRKN | H28: Vault | I28: 14W086CW | J28: WIRE | K28: 14W086CW.jpg
A29: HOOVER & STRONG | B29: 14KW 1.5MM X 1MM FLAT WIRE | C29: 14W1.5X1FW | D29: =Prices!$J$15 -> 190.7438 | F29: 10.8 | G29: ZD6FX4L3 | H29: Vault | I29: 14W1.5X1FW | J29: WIRE | K29: 14Y3.0FW.jpg
A30: LEACH GARNER-STERN METALS | B30: 14KW 1/8 BEZEL WIRE | C30: 14W1/8BW | D30: =Prices!$J$25 -> 209.81818 | F30: 3.07 | G30: ZF99WCC2 | H30: Vault | I30: 14W1/8BW | J30: WIRE | K30: SS1-4-125FW.jpg
A31: HOOVER & STRONG | B31: 14KW 2MM X 1MM FLAT WIRE | C31: 14W2X1FW | D31: =Prices!$J$15 -> 190.7438 | F31: 25.37 | G31: T4UJUAEK | H31: Vault | I31: 14W2X1FW | J31: WIRE
A32: HOOVER & STRONG | B32: 14KW 3MM X 1MM FLAT WIRE | C32: 14W3X1FW | D32: =Prices!$J$15 -> 190.7438 | F32: 38.66 | G32: 61AH9A9H | H32: Vault | I32: 14W3X1FW | J32: WIRE | K32: 14Y3.0FW.jpg
A33: HOOVER & STRONG | B33: 14KW 4MM X 30GA BEZEL WIRE | C33: 14W4.0BW | D33: =Prices!$J$25 -> 209.81818 | F33: 14.02 | G33: H6WRDXEK | H33: Vault | I33: 14W4.0BW | J33: WIRE | K33: 14W4MMBW.jpg
A34: HOOVER & STRONG | B34: 14KW 4MM ROUND WIRE | C34: 14W4.0RW | D34: =Prices!$J$15 -> 190.7438 | F34: 17.96 | G34: 3NNDQ82K | H34: Vault | I34: 14W4.0RW | J34: WIRE | K34: 14W160RSW_161223-145811.jpg
A35: HOOVER & STRONG | B35: 14KW 4MM X 2MM FLAT WIRE | C35: 14W4X2FW | D35: =Prices!$J$15 -> 190.7438 | F35: 6.82 | G35: HH64NHMN | H35: Vault | I35: 14W4X2FW | J35: WIRE
A36: HOOVER & STRONG | B36: 14KW 5MM X .010 BEZEL WIRE | C36: 14W5.0BW | D36: =Prices!$J$25 -> 209.81818 | F36: 16.17 | G36: 55CY4UPK | H36: Vault | I36: 14W5.0BW | J36: WIRE | K36: 14Y5.0FW.jpg
A37: HOOVER & STRONG | B37: 14KW 5MM X 1MM FLAT WIRE | C37: 14W5X1FW | D37: =Prices!$J$15 -> 190.7438 | F37: 21.71 | G37: AJA0DZ1V | H37: Vault | I37: 14W5X1FW | J37: WIRE
A38: HOOVER & STRONG | B38: 14KW PALLADIUM .040 ROUND SOFT WIRE | C38: 14WP040RSW | D38: =Prices!$J$13+3 -> 191.40816 | F38: 57.71 | G38: A60A3JUQ | H38: Vault | I38: 14WP040RSW | J38: WIRE
A39: HOOVER & STRONG | B39: 14KW PALLADIUM 4" X 2" X .040 FLAT SHEET | C39: 14WP040SH | D39: =Prices!$J$13+3 -> 191.40816 | F39: 46.74 | G39: 1A1P662N | H39: Vault | I39: 14WP040SH | J39: SHEET
A40: HOOVER & STRONG | B40: 14WPD 015 ROUND SOFT WIRE | C40: 14WPD015RW | D40: =Prices!$J$13+3 -> 191.40816 | F40: 1.63 | G40: VZHMR081 | H40: Vault | I40: 14WPD015RW | J40: WIRE
...
